Workbook

Sheet 00_Instruções_Básicas
A1: ='01_Preço'!A1
A2: GUIA DE INFORMAÇÕES BÁSICAS
A4: ='01_Preço'!A4 | D4: =_xlfn.CONCAT('01_Preço'!M4," ",'01_Preço'!O4)
A5: NOME EMPRESA PROPONENTE: | C5: ='01_Preço'!C5
A6: Nº CNPJ: | B6: ='01_Preço'!L5 | C6: Nº INSCRIÇÃO ESTADUAL: | D6: ='01_Preço'!Q5
A7: NOME REPRESENTANTE LEGAL: | C7: ='01_Preço'!C6
A8: Nº CPF: | B8: ='01_Preço'!L6 | C8: Nº DA IDENTIDADE: | D8: ='01_Preço'!Q6
A9: DATA DE EMISSÃO: | B9: ='01_Preço'!V5 | C9: BASE ECONÔMICA TRIBUTÁRIA: | D9: ='01_Preço'!V4
A10: ASSINATURA DO REPRESENTANTE LEGAL DA EMPRESA: | C10: ='01_Preço'!E7
A12: REFERE-SE A DISCIPLINA | B12: NOME DA ABA NA PLANILHA | C12: DESCRIÇÃO DA PLANILHA | D12: ORIENTAÇÕES BASICAS PARA O PREENCHIMENTO
A13: REFERE-SE A TODAS AS DISCIPLINAS E PLANILHAS | B13: 00_Instruções.Básicas | C13: Esta aba, a "00_Instruções.Básicas", é um guia com as informações e instruções básicas para o preenchimento da planilha de preço e eventogramas. Além desta, o arquivo Excel, inclui as seguintes abas: "01_Preço" com campos disponíveis para entrada dos dados da empresa bem como campos para preenchimento de valores unitários das disciplinas e demais dados solicitados, conforme regras do edital. "02_Sobressalent_Especif_CEMIG_D" com campos disponíveis para preenchimento de valores unitários dos itens sobressalentes listados. "03_Eventos.pagamentos" esta aba apresenta as informações sobre a distribuição dos valores em eventos de pagamento, é destinada a entrada da informação do referido mês de cumprimento de cada evento individualmente. "04_TOTALIZADORA" esta aba apresenta uma totalizadora com o gráfico da curva de distribuição de valores no tempo, PREÇO GLOBAL e campo disponível para preenchimento do valor da antecipação solicitada. | D13: Esta aba da planilha contém orientações básicas para o preenchimento das demais abas da planilha de preços e eventos. Para facilitar o preenchimento, as células que requerem informações, de acordo com as instruções do EDITAL, estão na cor amarela nas planilhas, as demais células que não necessitam de preenchimento neste momento / fase do edital estão bloqueadas. Além do preenchimento dos campos em amarelo, a empresa proponente deverá providenciar a assinatura das planilhas pelo representante legal da empresa.
A15: PREÇO | B15: 01_Preço | C15: É uma tabela destinada ao lançamento dos preços e impostos, correspondentes aos equipamentos, materiais e serviços do fornecimento. | D15: Preencher os campos em amarelo "LICITAÇÃO Nº", "BASE ECONÔMICA TRIBUTÁRIA:", "EMPRESA PROPONENTE", "Nº CNPJ", "Nº INSCRIÇÃO ESTADUAL", "REPRESENTANTE LEGAL", "Nº CPF", "Nº IDENTIDADE", "DATA DE EMISSÃO",com o número da licitação e os respectivos dados da empresa bem como a data da proposta e data da base econômica tributária. Tais dados serão automaticamente transferidos às demais abas. Preencher também, os campos das colunas "PREÇO UNITÁRIO (com todos os tributos) (R$)", "Identificação do Fornecedor ou Sub Fornecedor" e "CNAE" com os valores unitários respectivamente ofertados para os materiais e serviços das disciplinas, bem como os dados dos fornecedores, conforme requeridos. ATENÇÃO! Os campos das colunas de impostos, devem ser preenchidos somente após a adjudicação do vencedor do certame, em outro momento, conforme instruções do edital e demais documentação.
A17: PREÇO SOBRESSALENTES ATIVOS CEMIG D | B17: 02_Sobressalent_Especif_CEMIG_D | C17: É uma tabela destinada ao lançamento dos preços e impostos, correspondentes aos materiais sobressalente do escopo Cemig D. | D17: Preencher os campos em amarelo "VALOR TOTAL DO ITEM (R$) (com todos os Impostos, já incluso o ICMS a ser recolhido no Estado de destino.)",com o valor dos respectivos itens sobresssalentes listados na tabela. ATENÇÃO! Os campos das colunas de impostos, devem ser preenchidos somente após a adjudicação do vencedor do certame, em outro momento, conforme instruções do edital e demais documentação.
A19: Todas | B19: 02_Evento.pagamentos | C19: É uma tabela que apresenta os eventos, seus valores e coluna para lançamento do mês de conclusão para cada um dos eventos. | D19: Preencher os campos da coluna "Mês da proposta" com o mês de conclusão dos respectivos eventos, de acordo com as instruções do edital e demais documentações.
A21: Ambas Disciplinas | B21: 03_TOTALIZADORA | C21: É uma tabela destinada a apresentação do VALOR GLOBAL e da curva de desembolso mensal com o quantitativo de eventos e seus valores mensais. Apresenta também o campo para preenchimento do VALOR DE ANTECIPAÇÃO SOLICITADA, conforme regras definidas na documentação do edital. | D21: Planilha para apresentação dos valores, quantidades de eventos e da curva de desembolso. Preencher somente o campo "ANTECIPAÇÃO SOLICITADA" com o valor percentual solicitado de antecipação, sendo este limitado a 5% do valor do PREÇO GLOBAL da proposta, demais campos são carregados de forma automática de acordo com as planilhas de preços e eventos.

Sheet BM
A5: REFORMA E MODERNIZAÇÃO DE SALTO GRANDE
A7: BOLETIM DE MEDIÇÃO - Nº 03/2026
A8: Data de apresentação: | R8: 46037
A9: Nº do Contrato | D9: 4680007320 - 7321
A10: Mês de Referência | D10: 46037
A11: Empresa Contratada | D11: INSIGHT ENERGY
A12: Empresa Contratante | D12: CEMIG GERAÇÃO E TRANSMISSÃO SA
A13: Empresas Subcontratadas | D13: n/a
A15: DESCRIÇÃO DOS EVENTOS | M15: HISTÓRICO DE MEDIÇÃO | N15: MEDIÇÃO | P15: CONTA CORRENTE | T15: Para uso da CEMIG GT
A16: Mês do Evento | B16: Especificação Técnica | C16: Nº Evento | D16: Descrição do Evento (Conforme Contrato) | I16: Fornecedor | J16: Valor do Evento (P0) | K16: Valor do Reajuste | L16: Valor (P0 + Reajuste) | M16: Medições anteriores | N16: Valor cumprido | O16: Saldo do Evento | P16: Utilização de Conta Corrente | Q16: Evento Cedente | R16: Saldo do Evendo Cedente | T16: Análise Técnica de Cumprimento | U16: Comentário
A18: =IF(C18="","",_xlfn.XLOOKUP(C18,'03_Eventos_pagamentos'!$G$10:$G$901,'03_Eventos_pagamentos'!$E$10:$E$901)) | B18: 2.21 - Interferências civis | C18: ='03_Eventos_pagamentos'!G629 | D18: =IF(C18="","",_xlfn.XLOOKUP(C18,'[1]03_Eventos_pagamentos'!$F$10:$F$495,'[1]03_Eventos_pagamentos'!$G$10:$G$495)) | I18: INSIGHT | J18: ='03_Eventos_pagamentos'!O629 | K18: 0 | L18: =J18+K18 | M18: 0 | N18: =L18*0.3 | O18: =L18-N18
A19: =IF(C19="","",_xlfn.XLOOKUP(C19,'03_Eventos_pagamentos'!$G$10:$G$901,'03_Eventos_pagamentos'!$E$10:$E$901)) | B19: 2.21 - Interferências civis | C19: ='03_Eventos_pagamentos'!G643 | D19: =IF(C19="","",_xlfn.XLOOKUP(C19,'[1]03_Eventos_pagamentos'!$F$10:$F$495,'[1]03_Eventos_pagamentos'!$G$10:$G$495)) | I19: INSIGHT | J19: ='03_Eventos_pagamentos'!O643 | K19: 0 | L19: =J19+K19 | M19: 0 | N19: =L19
M20: 0
M21: 0
A22: Total | J22: =SUM(J18:J21) | K22: =SUM(K18:K21) | L22: =SUM(L18:L21) | M22: =SUM(M18:M21)
A24: VALOR TOTAL CUMPRIDO | N24: =SUM(N18:N21)
A27: Evidências de Cumprimento
A28: INSIGHT ENERGY - Relatório de Medição 003 - BM03
A30: Apresentado por:
C35: RICARDO FERREIRA PINTO | H35: Data:
A40: Para uso da CEMIG GT
A41: Parecer da CONTRATANTE (observações):
A42: Comentários no campo de análise da Engenhaira do Proprietário.
A49: Aferido por:
H54: Data:
A58: Aprovado por:
H63: Data:

Sheet 01_Preço
A1: PLANILHA DE PREÇOS E EVENTOGRAMAS EXECUÇÃO DAS OBRAS DE REFORMA E MODERNIZAÇÃO DA UHE SALTO GRANDE E MODERNIZAÇÃO E DIGITALIZAÇÃO DA SE UHE SALTO GRANDE – ATIVOS CEMIG D
A2: TABELA DE PREÇOS DOS EQUIPAMENTOS, MATERIAIS E SERVIÇOS DA REFORMA E MODERNIZAÇÃO DA UHE SALTO GRANDE E MODERNIZAÇÃO E DIGITALIZAÇÃO DA SE UHE SALTO GRANDE – ATIVOS CEMIG D
A4: OBJETO: CONTRATAÇÃO DE SERVIÇOS PARA EXECUÇÃO DA MODERNIZAÇÃO DA UHE SALTO GRANDE E MODERNIZAÇÃO E DIGITALIZAÇÂO DA SE UHE SALTO GRANDE | M4: LICITAÇÃO Nº | O4: 500-TK20335 | Q4: BASE ECONÔMICA TRIBUTÁRIA: | V4: Lucro Real
A5: EMPRESA PROPONENTE: | C5: INSIGHT ENERGIA SERVIÇOS ELETROMECÂNICOS LTDA. | K5: Nº CNPJ: | L5: 14.162.225/0001-59 | N5: Nº INSC ESTADUAL: | Q5: 90.698.627-29 | U5: DATA DE EMISSÃO: | V5: 45414
A6: REPRESENTANTE LEGAL: | C6: Fernanda Fagundes Hernandes | K6: Nº CPF: | L6: 078.184.519-00 | N6: Nº IDENTIDADE: | Q6: 104585167
A7: ASSINATURA DO REPRESENTANTE LEGAL:
K9: SERVIÇOS | O9: MATERIAIS/EQUIPAMENTOS
A10: ITEM / Nº | B10: TIPO DO ITEM (MATERIAL / SERVIÇO) | C10: BM | D10: MÊS/ANO CRONOGRAMA | E10: DESCRITIVO DOS MATERIAL / SERVIÇOS | F10: UNID. | G10: QUANT. | H10: PREÇO UNITÁRIO (com todos tributos) (R$) | I10: % | J10: R$ BM/Concluído | K10: Código de Tributação (LC 116/2003) | L10: ISS (%) | M10: Identificação do Fornecedor ou Sub Fornecedor | N10: CNAE | O10: Classif. Fiscal (NCM) | P10: Revenda (Sim / Não) | Q10: II (%) | R10: IPI (%) | S10: ICMS origem (%) | T10: ICMS destino (%) | U10: ICMS Substit. Tributária (%) | V10: PREÇO TOTAL (R$)
A11: 2.01 - Sistema de Supervisão e Controle e 2.10 - Sistema de Sincronismo | U11: =_xlfn.CONCAT("VALOR TOTAL DA ET ",A11,) | V11: =SUM(V12:V40)
A12: 2.01.01 | B12: SERVIÇO | E12: Engenharia e projeto executivo | F12: VB. | G12: 1 | H12: 1093825.5 | M12: INSIGHT/LCS LINK | V12: =G12*H12
C13: .
A14: 2.01.02 | B14: SERVIÇO | E14: Desmontagem e adequação dos painéis de controle existentes e respectiva infraestrutura de interligação, incluindo a execução de arranjos provisórios | F14: VB. | G14: 1 | H14: 1202760.3 | M14: INSIGHT ENERGY | V14: =G14*H14
C15: .
A16: 2.01.03 | B16: SERVIÇO | E16: Montagem eletromecânica completa | F16: VB. | G16: 1 | H16: 1433220.4 | M16: INSIGHT ENERGY | V16: =G16*H16
C17: .
A18: 2.01.04 | B18: SERVIÇO | E18: Supervisão, ensaios de campo e comissionamento | F18: VB. | G18: 1 | H18: 1944620.5 | M18: LCS LINK | V18: =G18*H18
C19: .
A20: 2.01.05 | B20: MATERIAL | E20: Painéis completos (+#UC) contendo a unidades de aquisição e controle para supervisão, comando e controle da Unidade Geradora, incluído sistema de parada de emergência | F20: CJ. | G20: 4 | H20: 996595.78 | M20: INSIGHT ENERGY | V20: =G20*H20 | W20: 3473818
C21: .
A22: 2.01.06 | B22: MATERIAL | E22: Painel completo (+AUC) para supervisão, comando e controle dos serviços auxiliares elétricos e mecânicos da casa de força e tomada d´água de Santo Antônio | F22: CJ. | G22: 1 | H22: 797753.84 | M22: INSIGHT ENERGY | V22: =G22*H22
C23: .
A24: 2.01.07 | B24: MATERIAL | E24: Painel completo (+VUC1) contendo a unidade de aquisição e controle (UAC) para supervisão do nível do reservatório de Santo Antônio | F24: CJ. | G24: 1 | H24: 328307.6 | M24: INSIGHT ENERGY | V24: =G24*H24
C25: .
A26: 2.01.08 | B26: MATERIAL | E26: Painel completo (+VUC2) contendo a unidade de aquisição e controle (UAC) para supervisão do nível do reservatório de Guanhães | F26: CJ. | G26: 1 | H26: 328307.6 | M26: INSIGHT ENERGY | V26: =G26*H26
C27: .
A28: 2.01.09 | B28: MATERIAL | E28: Painel completo (+VUC3) contendo a unidade de aquisição e controle (UAC) para supervisão, comando e controle das comportas de tomada d’água Santo Antônio e aquisição de nível dos reservatórios (Santo Antônio e Guanhães) | F28: CJ. | G28: 1 | H28: 328307.6 | M28: INSIGHT ENERGY | V28: =G28*H28
C29: .
A30: 2.01.10 | B30: MATERIAL | E30: Painel completo (+SUC) contendo a unidade de aquisição e controle (UAC) para a supervisão, comando e controle da subestação Salto Grande | F30: CJ. | G30: 1 | H30: 785598.22 | M30: INSIGHT ENERGY | V30: =G30*H30
C31: .
A32: 2.01.11 | B32: MATERIAL | E32: Painel completo contendo o módulo de comunicação (MCO) com o centro de operação, os equipamentos da rede de dados e os equipamentos do sistema de sincronismo de tempo - GPS | F32: CJ. | G32: 1 | H32: 485003.49 | M32: INSIGHT ENERGY | V32: =G32*H32
C33: .
A34: 2.01.12 | B34: MATERIAL | E34: Mobiliário completo para o Sistema Digital de Supervisão e Controle | F34: CJ. | G34: 1 | H34: 41647.43 | M34: INSIGHT ENERGY | V34: =G34*H34
C35: .
A36: 2.01.13 | B36: MATERIAL | E36: Estação de operação (EOP), Módulos de configuração e desenvolvimento (MCD) e impressora multifuncional | F36: CJ. | G36: 1 | H36: 113080.49 | M36: INSIGHT ENERGY | V36: =G36*H36
C37: .
A38: 2.01.14 | B38: MATERIAL | E38: Cópias e licenças dos diversos softwares, para o funcionamento integral, operação, visualização, configuração e manutenção do Sistema Digital de Supervisão e Controle | F38: CJ. | G38: 1 | H38: 218550.51 | M38: INSIGHT ENERGY | V38: =G38*H38
C39: .
A40: 2.01.15 | B40: MATERIAL | E40: Sistema de energia para alimentação ininterrupta em 220Vca | F40: CJ. | G40: 1 | H40: 39367.8 | M40: INSIGHT ENERGY | V40: =G40*H40
C41: .
A42: 2.02 - Sistema de Proteção | U42: =_xlfn.CONCAT("VALOR TOTAL DA ET ",A42,) | V42: =SUM(V43:V63)
...

Sheet Tabela de mês
A1: 1 | B1: 45474
A2: 2 | B2: 45505
A3: 3 | B3: 45536
A4: 4 | B4: 45566
A5: 5 | B5: 45597
A6: 6 | B6: 45627
A7: 7 | B7: 45658
A8: 8 | B8: 45689
A9: 9 | B9: 45717
A10: 10 | B10: 45748
A11: 11 | B11: 45778
A12: 12 | B12: 45809
... A68: 68 | B68: 47515
B69: 47543
B70: 47574
B71: 47604

Sheet 03_Eventos_pagamentos
A1: ='01_Preço'!A1
A2: TABELA DE EVENTOS DOS EQUIPAMENTOS, MATERIAIS E SERVIÇOS DA REFORMA E MODERNIZAÇÃO DA UHE SALTO GRANDE E MODERNIZAÇÃO E DIGITALIZAÇÃO DA SE UHE SALTO GRANDE – ATIVOS CEMIG D
A4: =_xlfn.CONCAT('01_Preço'!M4," ",'01_Preço'!O4) | B4: ='01_Preço'!A4 | L4: BASE ECONÔMICA TRIBUTÁRIA | M4: ='01_Preço'!V4
A5: EMPRESA PROPONENTE: | B5: ='01_Preço'!C5 | E5: INSC ESTADUAL: | L5: ='01_Preço'!Q5 | M5: Nº CNPJ: | O5: ='01_Preço'!L5
A6: REPRESENTANTE LEGAL: | B6: ='01_Preço'!C6 | E6: Nº IDENTIDADE: | L6: ='01_Preço'!Q6 | M6: Nº CPF: | O6: ='01_Preço'!L6
A7: ASSINATURA REPRESENTANTE LEGAL EMPRESA: | D7: ='01_Preço'!E7 | L7: DATA DE EMISSÃO | M7: ='01_Preço'!V5
A9: Especificação Técnica | B9: Item da Tab. Preços | C9: Tipo | D9: Descritivo do Item | E9: Mês Proposta | G9: Evento nº | H9: Execução | I9: Faturamento | J9: Código de nota | K9: Item segurado | L9: Descrição do Marco Principais / Evento | M9: % referente a ET | N9: Valor da ET | O9: Valor do Marco / Evento | P9: Mês de desembolso | Q9: Desembolso financeiro | S9: Faturamento realizado
A10: 2.01 - Sistema de Supervisão e Controle e 2.10 - Sincronismo | N10: =SUM(O11,O26,O31,O39,O51,O56,O57,O59,O58,O60,O61,O62,O63,O65,O64)
A11: ='01_Preço'!$A$11 | B11: ='01_Preço'!$A$12 | C11: ='01_Preço'!$B$12 | D11: ='01_Preço'!$E$12 | L11: ='01_Preço'!$E$12 | M11: =O11/$N$10 | O11: =SUM(O12:O25) | U11: LEGENDA
A12: ='01_Preço'!$A$11 | B12: ='01_Preço'!$A$12 | C12: ='01_Preço'!$B$12 | D12: ='01_Preço'!$E$12 | E12: 16 | F12: =VLOOKUP(E12,'Tabela de mês'!$A$1:$B$70,2,TRUE) | G12: 001-SER | H12: INSIGHT | I12: INSIGHT | J12: 7.01 | L12: Aprovação do Plano de Emissão de Documentos do Sistema de Supervisão e Controle | M12: =O12/$O$11 | O12: 21492.17 | S12: SIM | U12: VERDE | V12: EVENTO SEM ALTERAÇÃO
A13: ='01_Preço'!$A$11 | B13: ='01_Preço'!$A$12 | C13: ='01_Preço'!$B$12 | D13: ='01_Preço'!$E$12 | E13: 16 | F13: =VLOOKUP(E13,'Tabela de mês'!$A$1:$B$70,2,TRUE) | G13: 233-SER | H13: INSIGHT | I13: INSIGHT | L13: Aprovação do Plano de Emissão de Documentos do Sistema de Sincronismo | M13: =O13/$O$11 | O13: 21599.39 | S13: SIM | U13: AMARELO | V13: EVENTO ALTERADO
A14: ='01_Preço'!$A$11 | B14: ='01_Preço'!$A$12 | C14: ='01_Preço'!$B$12 | D14: ='01_Preço'!$E$12 | E14: 21 | F14: =VLOOKUP(E14,'Tabela de mês'!$A$1:$B$70,2,TRUE) | G14: 002-SER | H14: LCS LINK | I14: FAT. DIRETO | J14: 7.01 | L14: Aprovação da arquitetura e do Workstatement do Sistema de Supervisão e Controle | M14: =O14/$O$11 | O14: 64476.52 | U14: AZUL | V14: FATURAMENTO DIRETO
A15: ='01_Preço'!$A$11 | B15: ='01_Preço'!$A$12 | C15: ='01_Preço'!$B$12 | D15: ='01_Preço'!$E$12 | E15: 21 | F15: =VLOOKUP(E15,'Tabela de mês'!$A$1:$B$70,2,TRUE) | G15: 003-SER | H15: LCS LINK | I15: FAT. DIRETO | J15: 7.01 | L15: Aprovação dos Diagramas Lógicos das Unidades Funcionais | M15: =O15/$O$11 | O15: 64476.52
A16: ='01_Preço'!$A$11 | B16: ='01_Preço'!$A$12 | C16: ='01_Preço'!$B$12 | D16: ='01_Preço'!$E$12 | E16: 24 | F16: =VLOOKUP(E16,'Tabela de mês'!$A$1:$B$70,2,TRUE) | G16: 004-SER - A | H16: LCS LINK | I16: FAT. DIRETO | J16: 7.01 | L16: Aprovação completa dos Documentos do Projeto Executivo e de Fabricação do Sistema de Supervisão e Controle 1ª UF com paineis +AUC, +#UC, SUC e MCO | M16: =O16/$O$11 | O16: 103162.43
A17: ='01_Preço'!$A$11 | B17: ='01_Preço'!$A$12 | C17: ='01_Preço'!$B$12 | D17: ='01_Preço'!$E$12 | E17: 24 | F17: =VLOOKUP(E17,'Tabela de mês'!$A$1:$B$70,2,TRUE) | G17: 234-SER -A | H17: INSIGHT | I17: INSIGHT | J17: 7.01 | L17: Aprovação completa dos Documentos do Projeto Executivo e de Fabricação do Sistema de Sincronismo 1ª UF | M17: =O17/$O$11 | O17: 144476.52
A18: ='01_Preço'!$A$11 | B18: ='01_Preço'!$A$12 | C18: ='01_Preço'!$B$12 | D18: ='01_Preço'!$E$12 | E18: 35 | F18: =VLOOKUP(E18,'Tabela de mês'!$A$1:$B$70,2,TRUE) | G18: 004-SER - B | H18: LCS LINK | I18: FAT. DIRETO | J18: 7.01 | L18: Aprovação completa dos Documentos do Projeto Executivo e de Fabricação do Sistema de Supervisão e Controle 2ª UF com paineis +#UC | M18: =O18/$O$11 | O18: 51581.22
A19: ='01_Preço'!$A$11 | B19: ='01_Preço'!$A$12 | C19: ='01_Preço'!$B$12 | D19: ='01_Preço'!$E$12 | E19: 35 | F19: =VLOOKUP(E19,'Tabela de mês'!$A$1:$B$70,2,TRUE) | G19: 234-SER -B | H19: INSIGHT | I19: INSIGHT | J19: 7.01 | L19: Aprovação completa dos Documentos do Projeto Executivo e de Fabricação do Sistema de Sincronismo 2ª UF | M19: =O19/$O$11 | O19: 144476.52
A20: ='01_Preço'!$A$11 | B20: ='01_Preço'!$A$12 | C20: ='01_Preço'!$B$12 | D20: ='01_Preço'!$E$12 | E20: 48 | F20: =VLOOKUP(E20,'Tabela de mês'!$A$1:$B$70,2,TRUE) | G20: 004-SER - C | H20: LCS LINK | I20: FAT. DIRETO | J20: 7.01 | L20: Aprovação completa dos Documentos do Projeto Executivo e de Fabricação do Sistema de Supervisão e Controle 3ª UFcom paineis +#UC | M20: =O20/$O$11 | O20: 51581.22
A21: ='01_Preço'!$A$11 | B21: ='01_Preço'!$A$12 | C21: ='01_Preço'!$B$12 | D21: ='01_Preço'!$E$12 | E21: 48 | F21: =VLOOKUP(E21,'Tabela de mês'!$A$1:$B$70,2,TRUE) | G21: 234-SER -C | H21: INSIGHT | I21: INSIGHT | J21: 7.01 | L21: Aprovação completa dos Documentos do Projeto Executivo e de Fabricação do Sistema de Sincronismo 3ª UF | M21: =O21/$O$11 | O21: 144476.52
A22: ='01_Preço'!$A$11 | B22: ='01_Preço'!$A$12 | C22: ='01_Preço'!$B$12 | D22: ='01_Preço'!$E$12 | E22: 59 | F22: =VLOOKUP(E22,'Tabela de mês'!$A$1:$B$70,2,TRUE) | G22: 004-SER - D | H22: LCS LINK | I22: FAT. DIRETO | J22: 7.01 | L22: Aprovação completa dos Documentos do Projeto Executivo e de Fabricação do Sistema de Supervisão e Controle 4ª UF com paineis +#UC | M22: =O22/$O$11 | O22: 51581.22
A23: ='01_Preço'!$A$11 | B23: ='01_Preço'!$A$12 | C23: ='01_Preço'!$B$12 | D23: ='01_Preço'!$E$12 | E23: 59 | F23: =VLOOKUP(E23,'Tabela de mês'!$A$1:$B$70,2,TRUE) | G23: 234-SER -D | H23: INSIGHT | I23: INSIGHT | J23: 7.01 | L23: Aprovação completa dos Documentos do Projeto Executivo e de Fabricação do Sistema de Sincronismo 4ª UF | M23: =O23/$O$11 | O23: 144476.52
A24: ='01_Preço'!$A$11 | B24: ='01_Preço'!$A$12 | C24: ='01_Preço'!$B$12 | D24: ='01_Preço'!$E$12 | E24: 65 | F24: =VLOOKUP(E24,'Tabela de mês'!$A$1:$B$70,2,TRUE) | G24: 005-SER | H24: LCS LINK | I24: FAT. DIRETO | J24: 7.01 | L24: Aprovação da versão conforme construído do Projeto do Sistema de Supervisão e Controle | M24: =O24/$O$11 | O24: 42984.35
A25: ='01_Preço'!$A$11 | B25: ='01_Preço'!$A$12 | C25: ='01_Preço'!$B$12 | D25: ='01_Preço'!$E$12 | E25: 65 | F25: =VLOOKUP(E25,'Tabela de mês'!$A$1:$B$70,2,TRUE) | G25: 235-SER | H25: INSIGHT | I25: INSIGHT | J25: 7.01 | L25: Aprovação da versão conforme construído do Projeto do Sistema de Sincronismo | M25: =O25/$O$11 | O25: 42984.35
A26: ='01_Preço'!$A$11 | B26: ='01_Preço'!$A$14 | C26: ='01_Preço'!$B$14 | D26: Desmontagem eletromecânica completa | L26: ='01_Preço'!$E$14 | M26: =O26/$N$10 | O26: =SUM(O27:O30)
A27: ='01_Preço'!$A$11 | B27: ='01_Preço'!$A$14 | C27: ='01_Preço'!$B$14 | D27: Desmontagem eletromecânica completa | E27: 27 | F27: =VLOOKUP(E27,'Tabela de mês'!$A$1:$B$70,2,TRUE) | G27: 013-SER | H27: INSIGHT | I27: INSIGHT | J27: 7.02 | L27: Conclusão da Desmontagem de todos equipamentos e componentes do SDSC da 1ª UF, integrado aos demais equipamentos e sistemas | M27: =O27/$O$26 | O27: 300690.07 | P27: 25 | Q27: 168000
A28: ='01_Preço'!$A$11 | B28: ='01_Preço'!$A$14 | C28: ='01_Preço'!$B$14 | D28: Desmontagem eletromecânica completa | E28: 37 | F28: =VLOOKUP(E28,'Tabela de mês'!$A$1:$B$70,2,TRUE) | G28: 015-SER | H28: INSIGHT | I28: INSIGHT | J28: 7.02 | L28: Conclusão da Desmontagem de todos equipamentos e componentes do SDSC da 2ª UF, integrado aos demais equipamentos e sistemas | M28: =O28/$O$26 | O28: 300690.07 | P28: 35 | Q28: 168000
A29: ='01_Preço'!$A$11 | B29: ='01_Preço'!$A$14 | C29: ='01_Preço'!$B$14 | D29: Desmontagem eletromecânica completa | E29: 49 | F29: =VLOOKUP(E29,'Tabela de mês'!$A$1:$B$70,2,TRUE) | G29: 016-SER | H29: INSIGHT | I29: INSIGHT | J29: 7.02 | L29: Conclusão da Desmontagem de todos equipamentos e componentes do SDSC da 3ª UF, integrado aos demais equipamentos e sistemas | M29: =O29/$O$26 | O29: 300690.07 | P29: 46 | Q29: 168000
A30: ='01_Preço'!$A$11 | B30: ='01_Preço'!$A$14 | C30: ='01_Preço'!$B$14 | D30: Desmontagem eletromecânica completa | E30: 59 | F30: =VLOOKUP(E30,'Tabela de mês'!$A$1:$B$70,2,TRUE) | G30: 017-SER | H30: INSIGHT | I30: INSIGHT | J30: 7.02 | L30: Conclusão da Desmontagem de todos equipamentos e componentes do SDSC da 4ª UF, SE e Sala de Controle, integrado aos demais equipamentos e sistemas | M30: =O30/$O$26 | O30: 300690.07 | P30: 56 | Q30: 168000
A31: ='01_Preço'!$A$11 | B31: ='01_Preço'!$A$16 | C31: ='01_Preço'!$B$16 | D31: ='01_Preço'!$E$16 | L31: ='01_Preço'!$E$16 | M31: =O31/$N$10 | O31: =SUM(O32:O38)
A32: ='01_Preço'!$A$11 | B32: ='01_Preço'!$A$16 | C32: ='01_Preço'!$B$16 | D32: ='01_Preço'!$E$16 | E32: 31 | F32: =VLOOKUP(E32,'Tabela de mês'!$A$1:$B$70,2,TRUE) | G32: 238-SER | H32: INSIGHT | I32: INSIGHT | J32: 7.02 | L32: Conclusão da Adequações e Montagem de todos equipamentos e componentes do SDSC da 1ª UF, integrado aos demais equipamentos e sistemas | M32: =O32/$O$31 | O32: 300690.07
A33: ='01_Preço'!$A$11 | B33: ='01_Preço'!$A$16 | C33: ='01_Preço'!$B$16 | D33: ='01_Preço'!$E$16 | E33: 35 | F33: =VLOOKUP(E33,'Tabela de mês'!$A$1:$B$70,2,TRUE) | G33: 014-SER A | H33: INSIGHT | I33: INSIGHT | J33: 7.02 | L33: Conclusão das Adequações e Montagem de todos equipamentos e componentes do SDSC dos Tomada d'agua Santo antônio | M33: =O33/$O$31 | O33: 76820.04
A34: ='01_Preço'!$A$11 | B34: ='01_Preço'!$A$16 | C34: ='01_Preço'!$B$16 | D34: ='01_Preço'!$E$16 | E34: 40 | F34: =VLOOKUP(E34,'Tabela de mês'!$A$1:$B$70,2,TRUE) | G34: 014-SER B | H34: INSIGHT | I34: INSIGHT | J34: 7.02 | L34: Conclusão das Adequações e Montagem de todos equipamentos e componentes do SDSC dos Vertedouro Guanhães | M34: =O34/$O$31 | O34: 76820.03
A35: ='01_Preço'!$A$11 | B35: ='01_Preço'!$A$16 | C35: ='01_Preço'!$B$16 | D35: ='01_Preço'!$E$16 | E35: 40 | F35: =VLOOKUP(E35,'Tabela de mês'!$A$1:$B$70,2,TRUE) | G35: 014-SER C | H35: INSIGHT | I35: INSIGHT | J35: 7.02 | L35: Conclusão das Adequações e Montagem de todos equipamentos e componentes do SDSC do Vertedouro Santo Antônio | M35: =O35/$O$31 | O35: 76820.03
A36: ='01_Preço'!$A$11 | B36: ='01_Preço'!$A$16 | C36: ='01_Preço'!$B$16 | D36: ='01_Preço'!$E$16 | E36: 43 | F36: =VLOOKUP(E36,'Tabela de mês'!$A$1:$B$70,2,TRUE) | G36: 239-SER | H36: INSIGHT | I36: INSIGHT | J36: 7.02 | L36: Conclusão da Adequações e Montagem de todos equipamentos e componentes do SDSC da 2ª UF, integrado aos demais equipamentos e sistemas | M36: =O36/$O$31 | O36: 300690.07
A37: ='01_Preço'!$A$11 | B37: ='01_Preço'!$A$16 | C37: ='01_Preço'!$B$16 | D37: ='01_Preço'!$E$16 | E37: 55 | F37: =VLOOKUP(E37,'Tabela de mês'!$A$1:$B$70,2,TRUE) | G37: 240-SER | H37: INSIGHT | I37: INSIGHT | J37: 7.02 | L37: Conclusão da Adequações e Montagem de todos equipamentos e componentes do SDSC da 3ª UF, integrado aos demais equipamentos e sistemas | M37: =O37/$O$31 | O37: 300690.07
A38: ='01_Preço'!$A$11 | B38: ='01_Preço'!$A$16 | C38: ='01_Preço'!$B$16 | D38: ='01_Preço'!$E$16 | E38: 65 | F38: =VLOOKUP(E38,'Tabela de mês'!$A$1:$B$70,2,TRUE) | G38: 241-SER | H38: INSIGHT | I38: INSIGHT | J38: 7.02 | L38: Conclusão das adequações e Montagem de todos equipamentos e componentes do SDSC da 4ª UF, SE e Sala de Controle, integrado aos demais equipamentos e sistemas | M38: =O38/$O$31 | O38: 300690.07
A39: ='01_Preço'!$A$11 | B39: ='01_Preço'!$A$18 | C39: ='01_Preço'!$B$18 | D39: ='01_Preço'!$E$16 | L39: ='01_Preço'!$E$18 | M39: =O39/$N$10 | O39: =SUM(O40:O50)
A40: ='01_Preço'!$A$11 | B40: ='01_Preço'!$A$18 | C40: ='01_Preço'!$B$18 | D40: ='01_Preço'!$E$16 | E40: 33 | F40: =VLOOKUP(E40,'Tabela de mês'!$A$1:$B$70,2,TRUE) | G40: 018-SER | H40: LCS LINK | I40: FAT. DIRETO | J40: 7.02 | L40: Conclusão do Comissionamento estático do SDSC da 1ª UF, integrado aos demais equipamentos e sistemas | M40: =O40/$O$39 | O40: 175015.85
A41: ='01_Preço'!$A$11 | B41: ='01_Preço'!$A$18 | C41: ='01_Preço'!$B$18 | D41: ='01_Preço'!$E$16 | E41: 34 | F41: =VLOOKUP(E41,'Tabela de mês'!$A$1:$B$70,2,TRUE) | G41: 242-SER | H41: LCS LINK | I41: FAT. DIRETO | J41: 7.02 | L41: Conclusão do Comissionamento dinâmico do SDSC da 1ª UF, integrado aos demais equipamentos e sistemas | M41: =O41/$O$39 | O41: 408370.3
A42: ='01_Preço'!$A$11 | B42: ='01_Preço'!$A$18 | C42: ='01_Preço'!$B$18 | D42: ='01_Preço'!$E$16 | E42: 37 | F42: =VLOOKUP(E42,'Tabela de mês'!$A$1:$B$70,2,TRUE) | G42: 019-SER A | H42: LCS LINK | I42: FAT. DIRETO | J42: 7.02 | L42: Conclusão do Comissionamento do SDSC da Tomada d'Água Santo Antônio | M42: =O42/$O$39 | O42: 25928.27
...

Sheet 04_TOTALIZADORA (2)
A1: ='01_Preço'!A1
A2: TABELA TOTALIZADORA DOS PREÇOS DOS MATERIAIS E SERVIÇOS DA REFORMA E MODERNIZAÇÃO DA UHE SALTO GRANDE E MODERNIZAÇÃO E DIGITALIZAÇÃO DA SE UHE SALTO GRANDE – ATIVOS CEMIG D
A4: OBJETO: CONTRATAÇÃO DE SERVIÇOS PARA EXECUÇÃO DA MODERNIZAÇÃO DA UHE SALTO GRANDE | O4: =_xlfn.CONCAT('01_Preço'!M4," ",'01_Preço'!O4) | Q4: BASE ECONÔMICA TRIBUTÁRIA: | R4: ='01_Preço'!V4
A5: NOME EMPRESA PROPONENTE: | D5: ='01_Preço'!C5 | O5: Nº CNPJ: | P5: ='01_Preço'!L5 | Q5: Nº INSC ESTADUAL: | R5: ='01_Preço'!Q5
A6: NOME REPRESENTANTE LEGAL: | D6: ='01_Preço'!C6 | O6: Nº CPF: | P6: ='01_Preço'!L6 | Q6: Nº IDENTIDADE: | R6: ='01_Preço'!Q6
A7: ASSINATURA DO REPRESENTANTE LEGAL DA EMPRESA: | E7: ='01_Preço'!E7 | Q7: DATA DE EMISSÃO: | R7: ='01_Preço'!V5
A9: % DA ANTECIPAÇÃO SOLICITADA | D9: 0.05 | E9: VALOR ANTECIPAÇÃO SOLICITADA | M9: =D9*Q9 | O9: PREÇO GLOBAL | Q9: =O83
A12: MÊS | B12: ESCOPO CEMIG GT | D12: ESCOPO CEMIG D | F12: VALOR ACUMULADO (com todos os impostos) (R$) | G12: INSIGHT | H12: DESEMBOLSO ACUMULADO VALOR ACUMULADO | I12: FAT. DIRETO | J12: DESEMBOLSO TOTAL ACUMULADO VALOR ACUMULADO | K12: FATURAMENTO REALIZADO | L12: FATURAMENTO ACUMULADO | M12: PREÇO DA REFORMA E MODERNIZAÇÃO DA UHE SALTO GRANDE | Q12: =C84
B13: EVENTOS NO MÊS | C13: VALOR TOTAL MENSAL (com todos os impostos) (R$) | D13: EVENTOS NO MÊS | E13: VALOR TOTAL MENSAL (com todos os impostos) (R$) | G13: DESEMBOLSO MENSAL | I13: DESEMBOLSO MENSAL | M13: PREÇO DA MODERNIZAÇÃO E DIGITALIZAÇÃO DA SE UHE SALTO GRANDE - ATIVO CEMIG D | Q13: =E84
A14: 1 | B14: =SUM(COUNTIF('03_Eventos_pagamentos'!$E$11:$E$697,'04_TOTALIZADORA (2)'!A14)+COUNTIF('03_Eventos_pagamentos'!$E$766:$E$836,'04_TOTALIZADORA (2)'!A14)) | C14: =SUMIF('03_Eventos_pagamentos'!$E$11:$E$699,A14,'03_Eventos_pagamentos'!$O$11:$O$697)+SUMIF('03_Eventos_pagamentos'!$E$766:$E$836,A14,'03_Eventos_pagamentos'!$O$766:$O$836) | D14: =COUNTIF('03_Eventos_pagamentos'!$E$702:$E$763,'04_TOTALIZADORA (2)'!A14) | E14: =SUMIF('03_Eventos_pagamentos'!$E$702:$E$763,A14,'03_Eventos_pagamentos'!$O$702:$O$763) | F14: =C14+E14 | G14: =SUMIF('03_Eventos_pagamentos'!$P$11:$P$843,A15,'03_Eventos_pagamentos'!$Q$11:$Q$843) | I14: =SUMIFS( '03_Eventos_pagamentos'!$O$11:$O$843,'03_Eventos_pagamentos'!$E$11:$E$843,A14,'03_Eventos_pagamentos'!$I$11:$I$843,"FAT. DIRETO") | J14: =H14+I14 | K14: 0 | L14: =K14
A15: 2 à 15 | B15: =SUM(COUNTIF('03_Eventos_pagamentos'!$E$11:$E$697,'04_TOTALIZADORA (2)'!A15)+COUNTIF('03_Eventos_pagamentos'!$E$766:$E$836,'04_TOTALIZADORA (2)'!A15)) | C15: =SUMIF('03_Eventos_pagamentos'!$E$11:$E$699,A15,'03_Eventos_pagamentos'!$O$11:$O$697)+SUMIF('03_Eventos_pagamentos'!$E$766:$E$836,A15,'03_Eventos_pagamentos'!$O$766:$O$836) | D15: =COUNTIF('03_Eventos_pagamentos'!$E$702:$E$763,'04_TOTALIZADORA (2)'!A15) | E15: =SUMIF('03_Eventos_pagamentos'!$E$702:$E$763,A15,'03_Eventos_pagamentos'!$O$702:$O$763) | F15: =C15+E15+F14 | G15: =SUMIF('03_Eventos_pagamentos'!$P$11:$P$843,A16,'03_Eventos_pagamentos'!$Q$11:$Q$843) | H15: =G15+H14 | I15: =SUMIFS( '03_Eventos_pagamentos'!$O$11:$O$843,'03_Eventos_pagamentos'!$E$11:$E$843,A15,'03_Eventos_pagamentos'!$I$11:$I$843,"FAT. DIRETO") | J15: =G15+I15+J14 | K15: =R83 | L15: =K15+L14
A16: 3 | B16: =SUM(COUNTIF('03_Eventos_pagamentos'!$E$11:$E$697,'04_TOTALIZADORA (2)'!A16)+COUNTIF('03_Eventos_pagamentos'!$E$766:$E$836,'04_TOTALIZADORA (2)'!A16)) | C16: =SUMIF('03_Eventos_pagamentos'!$E$11:$E$699,A16,'03_Eventos_pagamentos'!$O$11:$O$697)+SUMIF('03_Eventos_pagamentos'!$E$766:$E$836,A16,'03_Eventos_pagamentos'!$O$766:$O$836) | D16: =COUNTIF('03_Eventos_pagamentos'!$E$702:$E$763,'04_TOTALIZADORA (2)'!A16) | E16: =SUMIF('03_Eventos_pagamentos'!$E$702:$E$763,A16,'03_Eventos_pagamentos'!$O$702:$O$763) | F16: =C16+E16+F15 | G16: =SUMIF('03_Eventos_pagamentos'!$P$11:$P$843,A17,'03_Eventos_pagamentos'!$Q$11:$Q$843) | H16: =G16+H15 | I16: =SUMIFS( '03_Eventos_pagamentos'!$O$11:$O$843,'03_Eventos_pagamentos'!$E$11:$E$843,A16,'03_Eventos_pagamentos'!$I$11:$I$843,"FAT. DIRETO") | J16: =G16+I16+J15 | L16: =K16+L15
A17: 4 | B17: =SUM(COUNTIF('03_Eventos_pagamentos'!$E$11:$E$697,'04_TOTALIZADORA (2)'!A17)+COUNTIF('03_Eventos_pagamentos'!$E$766:$E$836,'04_TOTALIZADORA (2)'!A17)) | C17: =SUMIF('03_Eventos_pagamentos'!$E$11:$E$699,A17,'03_Eventos_pagamentos'!$O$11:$O$697)+SUMIF('03_Eventos_pagamentos'!$E$766:$E$836,A17,'03_Eventos_pagamentos'!$O$766:$O$836) | D17: =COUNTIF('03_Eventos_pagamentos'!$E$702:$E$763,'04_TOTALIZADORA (2)'!A17) | E17: =SUMIF('03_Eventos_pagamentos'!$E$702:$E$763,A17,'03_Eventos_pagamentos'!$O$702:$O$763) | F17: =C17+E17+F16 | G17: =SUMIF('03_Eventos_pagamentos'!$P$11:$P$843,A18,'03_Eventos_pagamentos'!$Q$11:$Q$843) | H17: =G17+H16 | I17: =SUMIFS( '03_Eventos_pagamentos'!$O$11:$O$843,'03_Eventos_pagamentos'!$E$11:$E$843,A17,'03_Eventos_pagamentos'!$I$11:$I$843,"FAT. DIRETO") | J17: =G17+I17+J16 | L17: =K17+L16
A18: 5 | B18: =SUM(COUNTIF('03_Eventos_pagamentos'!$E$11:$E$697,'04_TOTALIZADORA (2)'!A18)+COUNTIF('03_Eventos_pagamentos'!$E$766:$E$836,'04_TOTALIZADORA (2)'!A18)) | C18: =SUMIF('03_Eventos_pagamentos'!$E$11:$E$699,A18,'03_Eventos_pagamentos'!$O$11:$O$697)+SUMIF('03_Eventos_pagamentos'!$E$766:$E$836,A18,'03_Eventos_pagamentos'!$O$766:$O$836) | D18: =COUNTIF('03_Eventos_pagamentos'!$E$702:$E$763,'04_TOTALIZADORA (2)'!A18) | E18: =SUMIF('03_Eventos_pagamentos'!$E$702:$E$763,A18,'03_Eventos_pagamentos'!$O$702:$O$763) | F18: =C18+E18+F17 | G18: =SUMIF('03_Eventos_pagamentos'!$P$11:$P$843,A19,'03_Eventos_pagamentos'!$Q$11:$Q$843) | H18: =G18+H17 | I18: =SUMIFS( '03_Eventos_pagamentos'!$O$11:$O$843,'03_Eventos_pagamentos'!$E$11:$E$843,A18,'03_Eventos_pagamentos'!$I$11:$I$843,"FAT. DIRETO") | J18: =G18+I18+J17 | L18: =K18+L17
A19: 6 | B19: =SUM(COUNTIF('03_Eventos_pagamentos'!$E$11:$E$697,'04_TOTALIZADORA (2)'!A19)+COUNTIF('03_Eventos_pagamentos'!$E$766:$E$836,'04_TOTALIZADORA (2)'!A19)) | C19: =SUMIF('03_Eventos_pagamentos'!$E$11:$E$699,A19,'03_Eventos_pagamentos'!$O$11:$O$697)+SUMIF('03_Eventos_pagamentos'!$E$766:$E$836,A19,'03_Eventos_pagamentos'!$O$766:$O$836) | D19: =COUNTIF('03_Eventos_pagamentos'!$E$702:$E$763,'04_TOTALIZADORA (2)'!A19) | E19: =SUMIF('03_Eventos_pagamentos'!$E$702:$E$763,A19,'03_Eventos_pagamentos'!$O$702:$O$763) | F19: =C19+E19+F18 | G19: =SUMIF('03_Eventos_pagamentos'!$P$11:$P$843,A20,'03_Eventos_pagamentos'!$Q$11:$Q$843) | H19: =G19+H18 | I19: =SUMIFS( '03_Eventos_pagamentos'!$O$11:$O$843,'03_Eventos_pagamentos'!$E$11:$E$843,A19,'03_Eventos_pagamentos'!$I$11:$I$843,"FAT. DIRETO") | J19: =G19+I19+J18 | L19: =K19+L18
A20: 7 | B20: =SUM(COUNTIF('03_Eventos_pagamentos'!$E$11:$E$697,'04_TOTALIZADORA (2)'!A20)+COUNTIF('03_Eventos_pagamentos'!$E$766:$E$836,'04_TOTALIZADORA (2)'!A20)) | C20: =SUMIF('03_Eventos_pagamentos'!$E$11:$E$699,A20,'03_Eventos_pagamentos'!$O$11:$O$697)+SUMIF('03_Eventos_pagamentos'!$E$766:$E$836,A20,'03_Eventos_pagamentos'!$O$766:$O$836) | D20: =COUNTIF('03_Eventos_pagamentos'!$E$702:$E$763,'04_TOTALIZADORA (2)'!A20) | E20: =SUMIF('03_Eventos_pagamentos'!$E$702:$E$763,A20,'03_Eventos_pagamentos'!$O$702:$O$763) | F20: =C20+E20+F19 | G20: =SUMIF('03_Eventos_pagamentos'!$P$11:$P$843,A21,'03_Eventos_pagamentos'!$Q$11:$Q$843) | H20: =G20+H19 | I20: =SUMIFS( '03_Eventos_pagamentos'!$O$11:$O$843,'03_Eventos_pagamentos'!$E$11:$E$843,A20,'03_Eventos_pagamentos'!$I$11:$I$843,"FAT. DIRETO") | J20: =G20+I20+J19 | L20: =K20+L19
A21: 8 | B21: =SUM(COUNTIF('03_Eventos_pagamentos'!$E$11:$E$697,'04_TOTALIZADORA (2)'!A21)+COUNTIF('03_Eventos_pagamentos'!$E$766:$E$836,'04_TOTALIZADORA (2)'!A21)) | C21: =SUMIF('03_Eventos_pagamentos'!$E$11:$E$699,A21,'03_Eventos_pagamentos'!$O$11:$O$697)+SUMIF('03_Eventos_pagamentos'!$E$766:$E$836,A21,'03_Eventos_pagamentos'!$O$766:$O$836) | D21: =COUNTIF('03_Eventos_pagamentos'!$E$702:$E$763,'04_TOTALIZADORA (2)'!A21) | E21: =SUMIF('03_Eventos_pagamentos'!$E$702:$E$763,A21,'03_Eventos_pagamentos'!$O$702:$O$763) | F21: =C21+E21+F20 | G21: =SUMIF('03_Eventos_pagamentos'!$P$11:$P$843,A22,'03_Eventos_pagamentos'!$Q$11:$Q$843) | H21: =G21+H20 | I21: =SUMIFS( '03_Eventos_pagamentos'!$O$11:$O$843,'03_Eventos_pagamentos'!$E$11:$E$843,A21,'03_Eventos_pagamentos'!$I$11:$I$843,"FAT. DIRETO") | J21: =G21+I21+J20 | L21: =K21+L20
A22: 9 | B22: =SUM(COUNTIF('03_Eventos_pagamentos'!$E$11:$E$697,'04_TOTALIZADORA (2)'!A22)+COUNTIF('03_Eventos_pagamentos'!$E$766:$E$836,'04_TOTALIZADORA (2)'!A22)) | C22: =SUMIF('03_Eventos_pagamentos'!$E$11:$E$699,A22,'03_Eventos_pagamentos'!$O$11:$O$697)+SUMIF('03_Eventos_pagamentos'!$E$766:$E$836,A22,'03_Eventos_pagamentos'!$O$766:$O$836) | D22: =COUNTIF('03_Eventos_pagamentos'!$E$702:$E$763,'04_TOTALIZADORA (2)'!A22) | E22: =SUMIF('03_Eventos_pagamentos'!$E$702:$E$763,A22,'03_Eventos_pagamentos'!$O$702:$O$763) | F22: =C22+E22+F21 | G22: =SUMIF('03_Eventos_pagamentos'!$P$11:$P$843,A23,'03_Eventos_pagamentos'!$Q$11:$Q$843) | H22: =G22+H21 | I22: =SUMIFS( '03_Eventos_pagamentos'!$O$11:$O$843,'03_Eventos_pagamentos'!$E$11:$E$843,A22,'03_Eventos_pagamentos'!$I$11:$I$843,"FAT. DIRETO") | J22: =G22+I22+J21 | L22: =K22+L21
A23: 10 | B23: =SUM(COUNTIF('03_Eventos_pagamentos'!$E$11:$E$697,'04_TOTALIZADORA (2)'!A23)+COUNTIF('03_Eventos_pagamentos'!$E$766:$E$836,'04_TOTALIZADORA (2)'!A23)) | C23: =SUMIF('03_Eventos_pagamentos'!$E$11:$E$699,A23,'03_Eventos_pagamentos'!$O$11:$O$697)+SUMIF('03_Eventos_pagamentos'!$E$766:$E$836,A23,'03_Eventos_pagamentos'!$O$766:$O$836) | D23: =COUNTIF('03_Eventos_pagamentos'!$E$702:$E$763,'04_TOTALIZADORA (2)'!A23) | E23: =SUMIF('03_Eventos_pagamentos'!$E$702:$E$763,A23,'03_Eventos_pagamentos'!$O$702:$O$763) | F23: =C23+E23+F22 | G23: =SUMIF('03_Eventos_pagamentos'!$P$11:$P$843,A24,'03_Eventos_pagamentos'!$Q$11:$Q$843) | H23: =G23+H22 | I23: =SUMIFS( '03_Eventos_pagamentos'!$O$11:$O$843,'03_Eventos_pagamentos'!$E$11:$E$843,A23,'03_Eventos_pagamentos'!$I$11:$I$843,"FAT. DIRETO") | J23: =G23+I23+J22 | L23: =K23+L22
A24: 11 | B24: =SUM(COUNTIF('03_Eventos_pagamentos'!$E$11:$E$697,'04_TOTALIZADORA (2)'!A24)+COUNTIF('03_Eventos_pagamentos'!$E$766:$E$836,'04_TOTALIZADORA (2)'!A24)) | C24: =SUMIF('03_Eventos_pagamentos'!$E$11:$E$699,A24,'03_Eventos_pagamentos'!$O$11:$O$697)+SUMIF('03_Eventos_pagamentos'!$E$766:$E$836,A24,'03_Eventos_pagamentos'!$O$766:$O$836) | D24: =COUNTIF('03_Eventos_pagamentos'!$E$702:$E$763,'04_TOTALIZADORA (2)'!A24) | E24: =SUMIF('03_Eventos_pagamentos'!$E$702:$E$763,A24,'03_Eventos_pagamentos'!$O$702:$O$763) | F24: =C24+E24+F23 | G24: =SUMIF('03_Eventos_pagamentos'!$P$11:$P$843,A25,'03_Eventos_pagamentos'!$Q$11:$Q$843) | H24: =G24+H23 | I24: =SUMIFS( '03_Eventos_pagamentos'!$O$11:$O$843,'03_Eventos_pagamentos'!$E$11:$E$843,A24,'03_Eventos_pagamentos'!$I$11:$I$843,"FAT. DIRETO") | J24: =G24+I24+J23 | L24: =K24+L23
A25: 12 | B25: =SUM(COUNTIF('03_Eventos_pagamentos'!$E$11:$E$697,'04_TOTALIZADORA (2)'!A25)+COUNTIF('03_Eventos_pagamentos'!$E$766:$E$836,'04_TOTALIZADORA (2)'!A25)) | C25: =SUMIF('03_Eventos_pagamentos'!$E$11:$E$699,A25,'03_Eventos_pagamentos'!$O$11:$O$697)+SUMIF('03_Eventos_pagamentos'!$E$766:$E$836,A25,'03_Eventos_pagamentos'!$O$766:$O$836) | D25: =COUNTIF('03_Eventos_pagamentos'!$E$702:$E$763,'04_TOTALIZADORA (2)'!A25) | E25: =SUMIF('03_Eventos_pagamentos'!$E$702:$E$763,A25,'03_Eventos_pagamentos'!$O$702:$O$763) | F25: =C25+E25+F24 | G25: =SUMIF('03_Eventos_pagamentos'!$P$11:$P$843,A26,'03_Eventos_pagamentos'!$Q$11:$Q$843) | H25: =G25+H24 | I25: =SUMIFS( '03_Eventos_pagamentos'!$O$11:$O$843,'03_Eventos_pagamentos'!$E$11:$E$843,A25,'03_Eventos_pagamentos'!$I$11:$I$843,"FAT. DIRETO") | J25: =G25+I25+J24 | L25: =K25+L24
A26: 13 | B26: =SUM(COUNTIF('03_Eventos_pagamentos'!$E$11:$E$697,'04_TOTALIZADORA (2)'!A26)+COUNTIF('03_Eventos_pagamentos'!$E$766:$E$836,'04_TOTALIZADORA (2)'!A26)) | C26: =SUMIF('03_Eventos_pagamentos'!$E$11:$E$699,A26,'03_Eventos_pagamentos'!$O$11:$O$697)+SUMIF('03_Eventos_pagamentos'!$E$766:$E$836,A26,'03_Eventos_pagamentos'!$O$766:$O$836) | D26: =COUNTIF('03_Eventos_pagamentos'!$E$702:$E$763,'04_TOTALIZADORA (2)'!A26) | E26: =SUMIF('03_Eventos_pagamentos'!$E$702:$E$763,A26,'03_Eventos_pagamentos'!$O$702:$O$763) | F26: =C26+E26+F25 | G26: =SUMIF('03_Eventos_pagamentos'!$P$11:$P$843,A27,'03_Eventos_pagamentos'!$Q$11:$Q$843) | H26: =G26+H25 | I26: =SUMIFS( '03_Eventos_pagamentos'!$O$11:$O$843,'03_Eventos_pagamentos'!$E$11:$E$843,A26,'03_Eventos_pagamentos'!$I$11:$I$843,"FAT. DIRETO") | J26: =G26+I26+J25 | L26: =K26+L25
A27: 14 | B27: =SUM(COUNTIF('03_Eventos_pagamentos'!$E$11:$E$697,'04_TOTALIZADORA (2)'!A27)+COUNTIF('03_Eventos_pagamentos'!$E$766:$E$836,'04_TOTALIZADORA (2)'!A27)) | C27: =SUMIF('03_Eventos_pagamentos'!$E$11:$E$699,A27,'03_Eventos_pagamentos'!$O$11:$O$697)+SUMIF('03_Eventos_pagamentos'!$E$766:$E$836,A27,'03_Eventos_pagamentos'!$O$766:$O$836) | D27: =COUNTIF('03_Eventos_pagamentos'!$E$702:$E$763,'04_TOTALIZADORA (2)'!A27) | E27: =SUMIF('03_Eventos_pagamentos'!$E$702:$E$763,A27,'03_Eventos_pagamentos'!$O$702:$O$763) | F27: =C27+E27+F26 | G27: =SUMIF('03_Eventos_pagamentos'!$P$11:$P$843,A28,'03_Eventos_pagamentos'!$Q$11:$Q$843) | H27: =G27+H26 | I27: =SUMIFS( '03_Eventos_pagamentos'!$O$11:$O$843,'03_Eventos_pagamentos'!$E$11:$E$843,A27,'03_Eventos_pagamentos'!$I$11:$I$843,"FAT. DIRETO") | J27: =G27+I27+J26 | L27: =K27+L26
A28: 15 | B28: =SUM(COUNTIF('03_Eventos_pagamentos'!$E$11:$E$697,'04_TOTALIZADORA (2)'!A28)+COUNTIF('03_Eventos_pagamentos'!$E$766:$E$836,'04_TOTALIZADORA (2)'!A28)) | C28: =SUMIF('03_Eventos_pagamentos'!$E$11:$E$699,A28,'03_Eventos_pagamentos'!$O$11:$O$697)+SUMIF('03_Eventos_pagamentos'!$E$766:$E$836,A28,'03_Eventos_pagamentos'!$O$766:$O$836) | D28: =COUNTIF('03_Eventos_pagamentos'!$E$702:$E$763,'04_TOTALIZADORA (2)'!A28) | E28: =SUMIF('03_Eventos_pagamentos'!$E$702:$E$763,A28,'03_Eventos_pagamentos'!$O$702:$O$763) | F28: =C28+E28+F27 | G28: =SUMIF('03_Eventos_pagamentos'!$P$11:$P$843,A29,'03_Eventos_pagamentos'!$Q$11:$Q$843) | H28: =G28+H27 | I28: =SUMIFS( '03_Eventos_pagamentos'!$O$11:$O$843,'03_Eventos_pagamentos'!$E$11:$E$843,A28,'03_Eventos_pagamentos'!$I$11:$I$843,"FAT. DIRETO") | J28: =G28+I28+J27 | K28: =0.85*412245.2 | L28: =K28+L27
A29: 16 | B29: =SUM(COUNTIF('03_Eventos_pagamentos'!$E$11:$E$697,'04_TOTALIZADORA (2)'!A29)+COUNTIF('03_Eventos_pagamentos'!$E$766:$E$836,'04_TOTALIZADORA (2)'!A29)) | C29: =SUMIF('03_Eventos_pagamentos'!$E$11:$E$699,A29,'03_Eventos_pagamentos'!$O$11:$O$697)+SUMIF('03_Eventos_pagamentos'!$E$766:$E$836,A29,'03_Eventos_pagamentos'!$O$766:$O$836) | D29: =COUNTIF('03_Eventos_pagamentos'!$E$702:$E$763,'04_TOTALIZADORA (2)'!A29) | E29: =SUMIF('03_Eventos_pagamentos'!$E$702:$E$763,A29,'03_Eventos_pagamentos'!$O$702:$O$763) | F29: =C29+E29+F28 | G29: =SUMIF('03_Eventos_pagamentos'!$P$11:$P$843,A30,'03_Eventos_pagamentos'!$Q$11:$Q$843) | H29: =G29+H28 | I29: =SUMIFS( '03_Eventos_pagamentos'!$O$11:$O$843,'03_Eventos_pagamentos'!$E$11:$E$843,A29,'03_Eventos_pagamentos'!$I$11:$I$843,"FAT. DIRETO") | J29: =G29+I29+J28 | L29: =K29+L28
A30: 17 | B30: =SUM(COUNTIF('03_Eventos_pagamentos'!$E$11:$E$697,'04_TOTALIZADORA (2)'!A30)+COUNTIF('03_Eventos_pagamentos'!$E$766:$E$836,'04_TOTALIZADORA (2)'!A30)) | C30: =SUMIF('03_Eventos_pagamentos'!$E$11:$E$699,A30,'03_Eventos_pagamentos'!$O$11:$O$697)+SUMIF('03_Eventos_pagamentos'!$E$766:$E$836,A30,'03_Eventos_pagamentos'!$O$766:$O$836) | D30: =COUNTIF('03_Eventos_pagamentos'!$E$702:$E$763,'04_TOTALIZADORA (2)'!A30) | E30: =SUMIF('03_Eventos_pagamentos'!$E$702:$E$763,A30,'03_Eventos_pagamentos'!$O$702:$O$763) | F30: =C30+E30+F29 | G30: =SUMIF('03_Eventos_pagamentos'!$P$11:$P$843,A31,'03_Eventos_pagamentos'!$Q$11:$Q$843) | H30: =G30+H29 | I30: =SUMIFS( '03_Eventos_pagamentos'!$O$11:$O$843,'03_Eventos_pagamentos'!$E$11:$E$843,A30,'03_Eventos_pagamentos'!$I$11:$I$843,"FAT. DIRETO") | J30: =G30+I30+J29 | K30: =0.85*800224.32 | L30: =K30+L29
A31: 18 | B31: =SUM(COUNTIF('03_Eventos_pagamentos'!$E$11:$E$697,'04_TOTALIZADORA (2)'!A31)+COUNTIF('03_Eventos_pagamentos'!$E$766:$E$836,'04_TOTALIZADORA (2)'!A31)) | C31: =SUMIF('03_Eventos_pagamentos'!$E$11:$E$699,A31,'03_Eventos_pagamentos'!$O$11:$O$697)+SUMIF('03_Eventos_pagamentos'!$E$766:$E$836,A31,'03_Eventos_pagamentos'!$O$766:$O$836) | D31: =COUNTIF('03_Eventos_pagamentos'!$E$702:$E$763,'04_TOTALIZADORA (2)'!A31) | E31: =SUMIF('03_Eventos_pagamentos'!$E$702:$E$763,A31,'03_Eventos_pagamentos'!$O$702:$O$763) | F31: =C31+E31+F30 | G31: =SUMIF('03_Eventos_pagamentos'!$P$11:$P$843,A32,'03_Eventos_pagamentos'!$Q$11:$Q$843) | H31: =G31+H30 | I31: =SUMIFS( '03_Eventos_pagamentos'!$O$11:$O$843,'03_Eventos_pagamentos'!$E$11:$E$843,A31,'03_Eventos_pagamentos'!$I$11:$I$843,"FAT. DIRETO") | J31: =G31+I31+J30 | L31: =K31+L30
A32: 19 | B32: =SUM(COUNTIF('03_Eventos_pagamentos'!$E$11:$E$697,'04_TOTALIZADORA (2)'!A32)+COUNTIF('03_Eventos_pagamentos'!$E$766:$E$836,'04_TOTALIZADORA (2)'!A32)) | C32: =SUMIF('03_Eventos_pagamentos'!$E$11:$E$699,A32,'03_Eventos_pagamentos'!$O$11:$O$697)+SUMIF('03_Eventos_pagamentos'!$E$766:$E$836,A32,'03_Eventos_pagamentos'!$O$766:$O$836) | D32: =COUNTIF('03_Eventos_pagamentos'!$E$702:$E$763,'04_TOTALIZADORA (2)'!A32) | E32: =SUMIF('03_Eventos_pagamentos'!$E$702:$E$763,A32,'03_Eventos_pagamentos'!$O$702:$O$763) | F32: =C32+E32+F31 | G32: =SUMIF('03_Eventos_pagamentos'!$P$11:$P$843,A33,'03_Eventos_pagamentos'!$Q$11:$Q$843) | H32: =G32+H31 | I32: =SUMIFS( '03_Eventos_pagamentos'!$O$11:$O$843,'03_Eventos_pagamentos'!$E$11:$E$843,A32,'03_Eventos_pagamentos'!$I$11:$I$843,"FAT. DIRETO") | J32: =G32+I32+J31 | L32: =K32+L31
A33: 20 | B33: =SUM(COUNTIF('03_Eventos_pagamentos'!$E$11:$E$697,'04_TOTALIZADORA (2)'!A33)+COUNTIF('03_Eventos_pagamentos'!$E$766:$E$836,'04_TOTALIZADORA (2)'!A33)) | C33: =SUMIF('03_Eventos_pagamentos'!$E$11:$E$699,A33,'03_Eventos_pagamentos'!$O$11:$O$697)+SUMIF('03_Eventos_pagamentos'!$E$766:$E$836,A33,'03_Eventos_pagamentos'!$O$766:$O$836) | D33: =COUNTIF('03_Eventos_pagamentos'!$E$702:$E$763,'04_TOTALIZADORA (2)'!A33) | E33: =SUMIF('03_Eventos_pagamentos'!$E$702:$E$763,A33,'03_Eventos_pagamentos'!$O$702:$O$763) | F33: =C33+E33+F32 | G33: =SUMIF('03_Eventos_pagamentos'!$P$11:$P$843,A34,'03_Eventos_pagamentos'!$Q$11:$Q$843) | H33: =G33+H32 | I33: =SUMIFS( '03_Eventos_pagamentos'!$O$11:$O$843,'03_Eventos_pagamentos'!$E$11:$E$843,A33,'03_Eventos_pagamentos'!$I$11:$I$843,"FAT. DIRETO") | J33: =G33+I33+J32 | L33: =K33+L32
A34: 21 | B34: =SUM(COUNTIF('03_Eventos_pagamentos'!$E$11:$E$697,'04_TOTALIZADORA (2)'!A34)+COUNTIF('03_Eventos_pagamentos'!$E$766:$E$836,'04_TOTALIZADORA (2)'!A34)) | C34: =SUMIF('03_Eventos_pagamentos'!$E$11:$E$699,A34,'03_Eventos_pagamentos'!$O$11:$O$697)+SUMIF('03_Eventos_pagamentos'!$E$766:$E$836,A34,'03_Eventos_pagamentos'!$O$766:$O$836) | D34: =COUNTIF('03_Eventos_pagamentos'!$E$702:$E$763,'04_TOTALIZADORA (2)'!A34) | E34: =SUMIF('03_Eventos_pagamentos'!$E$702:$E$763,A34,'03_Eventos_pagamentos'!$O$702:$O$763) | F34: =C34+E34+F33 | G34: =SUMIF('03_Eventos_pagamentos'!$P$11:$P$843,A35,'03_Eventos_pagamentos'!$Q$11:$Q$843) | H34: =G34+H33 | I34: =SUMIFS( '03_Eventos_pagamentos'!$O$11:$O$843,'03_Eventos_pagamentos'!$E$11:$E$843,A34,'03_Eventos_pagamentos'!$I$11:$I$843,"FAT. DIRETO") | J34: =G34+I34+J33 | L34: =K34+L33
A35: 22 | B35: =SUM(COUNTIF('03_Eventos_pagamentos'!$E$11:$E$697,'04_TOTALIZADORA (2)'!A35)+COUNTIF('03_Eventos_pagamentos'!$E$766:$E$836,'04_TOTALIZADORA (2)'!A35)) | C35: =SUMIF('03_Eventos_pagamentos'!$E$11:$E$699,A35,'03_Eventos_pagamentos'!$O$11:$O$697)+SUMIF('03_Eventos_pagamentos'!$E$766:$E$836,A35,'03_Eventos_pagamentos'!$O$766:$O$836) | D35: =COUNTIF('03_Eventos_pagamentos'!$E$702:$E$763,'04_TOTALIZADORA (2)'!A35) | E35: =SUMIF('03_Eventos_pagamentos'!$E$702:$E$763,A35,'03_Eventos_pagamentos'!$O$702:$O$763) | F35: =C35+E35+F34 | G35: =SUMIF('03_Eventos_pagamentos'!$P$11:$P$843,A36,'03_Eventos_pagamentos'!$Q$11:$Q$843) | H35: =G35+H34 | I35: =SUMIFS( '03_Eventos_pagamentos'!$O$11:$O$843,'03_Eventos_pagamentos'!$E$11:$E$843,A35,'03_Eventos_pagamentos'!$I$11:$I$843,"FAT. DIRETO") | J35: =G35+I35+J34 | L35: =K35+L34
A36: 23 | B36: =SUM(COUNTIF('03_Eventos_pagamentos'!$E$11:$E$697,'04_TOTALIZADORA (2)'!A36)+COUNTIF('03_Eventos_pagamentos'!$E$766:$E$836,'04_TOTALIZADORA (2)'!A36)) | C36: =SUMIF('03_Eventos_pagamentos'!$E$11:$E$699,A36,'03_Eventos_pagamentos'!$O$11:$O$697)+SUMIF('03_Eventos_pagamentos'!$E$766:$E$836,A36,'03_Eventos_pagamentos'!$O$766:$O$836) | D36: =COUNTIF('03_Eventos_pagamentos'!$E$702:$E$763,'04_TOTALIZADORA (2)'!A36) | E36: =SUMIF('03_Eventos_pagamentos'!$E$702:$E$763,A36,'03_Eventos_pagamentos'!$O$702:$O$763) | F36: =C36+E36+F35 | G36: =SUMIF('03_Eventos_pagamentos'!$P$11:$P$843,A37,'03_Eventos_pagamentos'!$Q$11:$Q$843) | H36: =G36+H35 | I36: =SUMIFS( '03_Eventos_pagamentos'!$O$11:$O$843,'03_Eventos_pagamentos'!$E$11:$E$843,A36,'03_Eventos_pagamentos'!$I$11:$I$843,"FAT. DIRETO") | J36: =G36+I36+J35 | L36: =K36+L35
A37: 24 | B37: =SUM(COUNTIF('03_Eventos_pagamentos'!$E$11:$E$697,'04_TOTALIZADORA (2)'!A37)+COUNTIF('03_Eventos_pagamentos'!$E$766:$E$836,'04_TOTALIZADORA (2)'!A37)) | C37: =SUMIF('03_Eventos_pagamentos'!$E$11:$E$699,A37,'03_Eventos_pagamentos'!$O$11:$O$697)+SUMIF('03_Eventos_pagamentos'!$E$766:$E$836,A37,'03_Eventos_pagamentos'!$O$766:$O$836) | D37: =COUNTIF('03_Eventos_pagamentos'!$E$702:$E$763,'04_TOTALIZADORA (2)'!A37) | E37: =SUMIF('03_Eventos_pagamentos'!$E$702:$E$763,A37,'03_Eventos_pagamentos'!$O$702:$O$763) | F37: =C37+E37+F36 | G37: =SUMIF('03_Eventos_pagamentos'!$P$11:$P$843,A38,'03_Eventos_pagamentos'!$Q$11:$Q$843) | H37: =G37+H36 | I37: =SUMIFS( '03_Eventos_pagamentos'!$O$11:$O$843,'03_Eventos_pagamentos'!$E$11:$E$843,A37,'03_Eventos_pagamentos'!$I$11:$I$843,"FAT. DIRETO") | J37: =G37+I37+J36 | L37: =K37+L36
A38: 25 | B38: =SUM(COUNTIF('03_Eventos_pagamentos'!$E$11:$E$697,'04_TOTALIZADORA (2)'!A38)+COUNTIF('03_Eventos_pagamentos'!$E$766:$E$836,'04_TOTALIZADORA (2)'!A38)) | C38: =SUMIF('03_Eventos_pagamentos'!$E$11:$E$699,A38,'03_Eventos_pagamentos'!$O$11:$O$697)+SUMIF('03_Eventos_pagamentos'!$E$766:$E$836,A38,'03_Eventos_pagamentos'!$O$766:$O$836) | D38: =COUNTIF('03_Eventos_pagamentos'!$E$702:$E$763,'04_TOTALIZADORA (2)'!A38) | E38: =SUMIF('03_Eventos_pagamentos'!$E$702:$E$763,A38,'03_Eventos_pagamentos'!$O$702:$O$763) | F38: =C38+E38+F37 | G38: =SUMIF('03_Eventos_pagamentos'!$P$11:$P$843,A39,'03_Eventos_pagamentos'!$Q$11:$Q$843) | H38: =G38+H37 | I38: =SUMIFS( '03_Eventos_pagamentos'!$O$11:$O$843,'03_Eventos_pagamentos'!$E$11:$E$843,A38,'03_Eventos_pagamentos'!$I$11:$I$843,"FAT. DIRETO") | J38: =G38+I38+J37 | L38: =K38+L37
A39: 26 | B39: =SUM(COUNTIF('03_Eventos_pagamentos'!$E$11:$E$697,'04_TOTALIZADORA (2)'!A39)+COUNTIF('03_Eventos_pagamentos'!$E$766:$E$836,'04_TOTALIZADORA (2)'!A39)) | C39: =SUMIF('03_Eventos_pagamentos'!$E$11:$E$699,A39,'03_Eventos_pagamentos'!$O$11:$O$697)+SUMIF('03_Eventos_pagamentos'!$E$766:$E$836,A39,'03_Eventos_pagamentos'!$O$766:$O$836) | D39: =COUNTIF('03_Eventos_pagamentos'!$E$702:$E$763,'04_TOTALIZADORA (2)'!A39) | E39: =SUMIF('03_Eventos_pagamentos'!$E$702:$E$763,A39,'03_Eventos_pagamentos'!$O$702:$O$763) | F39: =C39+E39+F38 | G39: =SUMIF('03_Eventos_pagamentos'!$P$11:$P$843,A40,'03_Eventos_pagamentos'!$Q$11:$Q$843) | H39: =G39+H38 | I39: =SUMIFS( '03_Eventos_pagamentos'!$O$11:$O$843,'03_Eventos_pagamentos'!$E$11:$E$843,A39,'03_Eventos_pagamentos'!$I$11:$I$843,"FAT. DIRETO") | J39: =G39+I39+J38 | L39: =K39+L38
A40: 27 | B40: =SUM(COUNTIF('03_Eventos_pagamentos'!$E$11:$E$697,'04_TOTALIZADORA (2)'!A40)+COUNTIF('03_Eventos_pagamentos'!$E$766:$E$836,'04_TOTALIZADORA (2)'!A40)) | C40: =SUMIF('03_Eventos_pagamentos'!$E$11:$E$699,A40,'03_Eventos_pagamentos'!$O$11:$O$697)+SUMIF('03_Eventos_pagamentos'!$E$766:$E$836,A40,'03_Eventos_pagamentos'!$O$766:$O$836) | D40: =COUNTIF('03_Eventos_pagamentos'!$E$702:$E$763,'04_TOTALIZADORA (2)'!A40) | E40: =SUMIF('03_Eventos_pagamentos'!$E$702:$E$763,A40,'03_Eventos_pagamentos'!$O$702:$O$763) | F40: =C40+E40+F39 | G40: =SUMIF('03_Eventos_pagamentos'!$P$11:$P$843,A41,'03_Eventos_pagamentos'!$Q$11:$Q$843) | H40: =G40+H39 | I40: =SUMIFS( '03_Eventos_pagamentos'!$O$11:$O$843,'03_Eventos_pagamentos'!$E$11:$E$843,A40,'03_Eventos_pagamentos'!$I$11:$I$843,"FAT. DIRETO") | J40: =G40+I40+J39 | L40: =K40+L39
A41: 28 | B41: =SUM(COUNTIF('03_Eventos_pagamentos'!$E$11:$E$697,'04_TOTALIZADORA (2)'!A41)+COUNTIF('03_Eventos_pagamentos'!$E$766:$E$836,'04_TOTALIZADORA (2)'!A41)) | C41: =SUMIF('03_Eventos_pagamentos'!$E$11:$E$699,A41,'03_Eventos_pagamentos'!$O$11:$O$697)+SUMIF('03_Eventos_pagamentos'!$E$766:$E$836,A41,'03_Eventos_pagamentos'!$O$766:$O$836) | D41: =COUNTIF('03_Eventos_pagamentos'!$E$702:$E$763,'04_TOTALIZADORA (2)'!A41) | E41: =SUMIF('03_Eventos_pagamentos'!$E$702:$E$763,A41,'03_Eventos_pagamentos'!$O$702:$O$763) | F41: =C41+E41+F40 | G41: =SUMIF('03_Eventos_pagamentos'!$P$11:$P$843,A42,'03_Eventos_pagamentos'!$Q$11:$Q$843) | H41: =G41+H40 | I41: =SUMIFS( '03_Eventos_pagamentos'!$O$11:$O$843,'03_Eventos_pagamentos'!$E$11:$E$843,A41,'03_Eventos_pagamentos'!$I$11:$I$843,"FAT. DIRETO") | J41: =G41+I41+J40 | L41: =K41+L40
A42: 29 | B42: =SUM(COUNTIF('03_Eventos_pagamentos'!$E$11:$E$697,'04_TOTALIZADORA (2)'!A42)+COUNTIF('03_Eventos_pagamentos'!$E$766:$E$836,'04_TOTALIZADORA (2)'!A42)) | C42: =SUMIF('03_Eventos_pagamentos'!$E$11:$E$699,A42,'03_Eventos_pagamentos'!$O$11:$O$697)+SUMIF('03_Eventos_pagamentos'!$E$766:$E$836,A42,'03_Eventos_pagamentos'!$O$766:$O$836) | D42: =COUNTIF('03_Eventos_pagamentos'!$E$702:$E$763,'04_TOTALIZADORA (2)'!A42) | E42: =SUMIF('03_Eventos_pagamentos'!$E$702:$E$763,A42,'03_Eventos_pagamentos'!$O$702:$O$763) | F42: =C42+E42+F41 | G42: =SUMIF('03_Eventos_pagamentos'!$P$11:$P$843,A43,'03_Eventos_pagamentos'!$Q$11:$Q$843) | H42: =G42+H41 | I42: =SUMIFS( '03_Eventos_pagamentos'!$O$11:$O$843,'03_Eventos_pagamentos'!$E$11:$E$843,A42,'03_Eventos_pagamentos'!$I$11:$I$843,"FAT. DIRETO") | J42: =G42+I42+J41 | L42: =K42+L41
... A78: 65 | B78: =SUM(COUNTIF('03_Eventos_pagamentos'!$E$11:$E$697,'04_TOTALIZADORA (2)'!A78)+COUNTIF('03_Eventos_pagamentos'!$E$766:$E$836,'04_TOTALIZADORA (2)'!A78)) | C78: =SUMIF('03_Eventos_pagamentos'!$E$11:$E$699,A78,'03_Eventos_pagamentos'!$O$11:$O$697)+SUMIF('03_Eventos_pagamentos'!$E$766:$E$836,A78,'03_Eventos_pagamentos'!$O$766:$O$836) | D78: =COUNTIF('03_Eventos_pagamentos'!$E$702:$E$763,'04_TOTALIZADORA (2)'!A78) | E78: =SUMIF('03_Eventos_pagamentos'!$E$702:$E$763,A78,'03_Eventos_pagamentos'!$O$702:$O$763) | F78: =C78+E78+F77 | G78: =SUMIF('03_Eventos_pagamentos'!$P$11:$P$843,A79,'03_Eventos_pagamentos'!$Q$11:$Q$843) | H78: =G78+H77 | I78: =SUMIFS( '03_Eventos_pagamentos'!$O$11:$O$843,'03_Eventos_pagamentos'!$E$11:$E$843,A78,'03_Eventos_pagamentos'!$I$11:$I$843,"FAT. DIRETO") | J78: =G78+I78+J77 | L78: =K78+L77
A79: 66 | B79: =SUM(COUNTIF('03_Eventos_pagamentos'!$E$11:$E$697,'04_TOTALIZADORA (2)'!A79)+COUNTIF('03_Eventos_pagamentos'!$E$766:$E$836,'04_TOTALIZADORA (2)'!A79)) | C79: =SUMIF('03_Eventos_pagamentos'!$E$11:$E$699,A79,'03_Eventos_pagamentos'!$O$11:$O$697)+SUMIF('03_Eventos_pagamentos'!$E$766:$E$836,A79,'03_Eventos_pagamentos'!$O$766:$O$836) | D79: =COUNTIF('03_Eventos_pagamentos'!$E$702:$E$763,'04_TOTALIZADORA (2)'!A79) | E79: =SUMIF('03_Eventos_pagamentos'!$E$702:$E$763,A79,'03_Eventos_pagamentos'!$O$702:$O$763) | F79: =C79+E79+F78 | G79: =SUMIF('03_Eventos_pagamentos'!$P$11:$P$843,A80,'03_Eventos_pagamentos'!$Q$11:$Q$843) | H79: =G79+H78 | I79: =SUMIFS( '03_Eventos_pagamentos'!$O$11:$O$843,'03_Eventos_pagamentos'!$E$11:$E$843,A79,'03_Eventos_pagamentos'!$I$11:$I$843,"FAT. DIRETO") | J79: =G79+I79+J78 | L79: =K79+L78 | Q79: VALOR AMORTIZADO | R79: =(SUM(K28,K30)/0.85)*0.15
...

Sheet 04_TOTALIZADORA
A1: ='01_Preço'!A1
A2: TABELA TOTALIZADORA DOS PREÇOS DOS MATERIAIS E SERVIÇOS DA REFORMA E MODERNIZAÇÃO DA UHE SALTO GRANDE E MODERNIZAÇÃO E DIGITALIZAÇÃO DA SE UHE SALTO GRANDE – ATIVOS CEMIG D
A4: OBJETO: CONTRATAÇÃO DE SERVIÇOS PARA EXECUÇÃO DA MODERNIZAÇÃO DA UHE SALTO GRANDE | U4: =_xlfn.CONCAT('01_Preço'!M4," ",'01_Preço'!O4) | W4: BASE ECONÔMICA TRIBUTÁRIA: | X4: ='01_Preço'!V4
A5: NOME EMPRESA PROPONENTE: | D5: ='01_Preço'!C5 | U5: Nº CNPJ: | V5: ='01_Preço'!L5 | W5: Nº INSC ESTADUAL: | X5: ='01_Preço'!Q5
A6: NOME REPRESENTANTE LEGAL: | D6: ='01_Preço'!C6 | U6: Nº CPF: | V6: ='01_Preço'!L6 | W6: Nº IDENTIDADE: | X6: ='01_Preço'!Q6
A7: ASSINATURA DO REPRESENTANTE LEGAL DA EMPRESA: | E7: ='01_Preço'!E7 | W7: DATA DE EMISSÃO: | X7: ='01_Preço'!V5
A9: % DA ANTECIPAÇÃO SOLICITADA | D9: 0.05 | E9: VALOR ANTECIPAÇÃO SOLICITADA | G9: Amortização | H9: =SUM(H14:H82) | S9: =D9*W9 | U9: PREÇO GLOBAL | W9: =U83
G10: Entrada | H10: =O15
A12: MÊS | B12: ESCOPO CEMIG GT | D12: ESCOPO CEMIG D | F12: VALOR ACUMULADO (com todos os impostos) (R$) | K12: INSIGHT | L12: DESEMBOLSO ACUMULADO VALOR ACUMULADO | M12: FAT. DIRETO | N12: DESEMBOLSO TOTAL ACUMULADO VALOR ACUMULADO | O12: FATURAMENTO REALIZADO | P12: FATURAMENTO ACUMULADO | Q12: PROGRAMAÇÃO DE PEDIDOS REALIZADOS | R12: PROGRAMAÇÃO ACUMULADA DE PEDIDOS REALIZADOS | S12: PREÇO DA REFORMA E MODERNIZAÇÃO DA UHE SALTO GRANDE | W12: =C84
B13: EVENTOS NO MÊS | C13: VALOR TOTAL MENSAL (com todos os impostos) (R$) | D13: EVENTOS NO MÊS | E13: VALOR TOTAL MENSAL (com todos os impostos) (R$) | G13: VALOR DA MEDIÇÃO PELA INSIGHT | H13: VALOR A AMORTIZAR | I13: VALOR PARA ENTRAR EM CAIXA DA INSIGHT | J13: VALOR A RECEBER (INSIGHT + DIRETO) | K13: DESEMBOLSO MENSAL | M13: DESEMBOLSO MENSAL | S13: PREÇO DA MODERNIZAÇÃO E DIGITALIZAÇÃO DA SE UHE SALTO GRANDE - ATIVO CEMIG D | W13: =E84
A14: 1 | B14: =SUM(COUNTIF('03_Eventos_pagamentos'!$E$11:$E$697,'04_TOTALIZADORA'!A14)+COUNTIF('03_Eventos_pagamentos'!$E$766:$E$836,'04_TOTALIZADORA'!A14)) | C14: =SUMIF('03_Eventos_pagamentos'!$E$11:$E$699,A14,'03_Eventos_pagamentos'!$O$11:$O$697)+SUMIF('03_Eventos_pagamentos'!$E$766:$E$836,A14,'03_Eventos_pagamentos'!$O$766:$O$836) | D14: =COUNTIF('03_Eventos_pagamentos'!$E$702:$E$763,'04_TOTALIZADORA'!A14) | E14: =SUMIF('03_Eventos_pagamentos'!$E$702:$E$763,A14,'03_Eventos_pagamentos'!$O$702:$O$763) | F14: =C14+E14 | G14: =SUMIF('03_Eventos_pagamentos'!$E$11:$E$699,F14,'03_Eventos_pagamentos'!$O$11:$O$697)+SUMIF('03_Eventos_pagamentos'!$E$766:$E$836,F14,'03_Eventos_pagamentos'!$O$766:$O$836) | H14: =SUMIF('03_Eventos_pagamentos'!$E$702:$E$763,F14,'03_Eventos_pagamentos'!$O$702:$O$763) | I14: =H10 | J14: =I14+M14 | K14: =SUMIF('03_Eventos_pagamentos'!$P$11:$P$843,A15,'03_Eventos_pagamentos'!$Q$11:$Q$843) | M14: =SUMIFS( '03_Eventos_pagamentos'!$O$11:$O$843,'03_Eventos_pagamentos'!$E$11:$E$843,A14,'03_Eventos_pagamentos'!$I$11:$I$843,"FAT. DIRETO") | N14: =L14+M14 | O14: 0 | P14: =O14 | Q14: 9546933.1 | R14: =Q14
A15: 2 | B15: =SUM(COUNTIF('03_Eventos_pagamentos'!$E$11:$E$697,'04_TOTALIZADORA'!A15)+COUNTIF('03_Eventos_pagamentos'!$E$766:$E$836,'04_TOTALIZADORA'!A15)) | C15: =SUMIF('03_Eventos_pagamentos'!$E$11:$E$699,A15,'03_Eventos_pagamentos'!$O$11:$O$697)+SUMIF('03_Eventos_pagamentos'!$E$766:$E$836,A15,'03_Eventos_pagamentos'!$O$766:$O$836) | D15: =COUNTIF('03_Eventos_pagamentos'!$E$702:$E$763,'04_TOTALIZADORA'!A15) | E15: =SUMIF('03_Eventos_pagamentos'!$E$702:$E$763,A15,'03_Eventos_pagamentos'!$O$702:$O$763) | F15: =C15+E15+F14 | H15: =SUMIF('03_Eventos_pagamentos'!$E$702:$E$763,F15,'03_Eventos_pagamentos'!$O$702:$O$763) | I15: =G15-H15 | J15: =I15+M15 | K15: =SUMIF('03_Eventos_pagamentos'!$P$11:$P$843,A16,'03_Eventos_pagamentos'!$Q$11:$Q$843) | L15: =K15+L14 | M15: =SUMIFS( '03_Eventos_pagamentos'!$O$11:$O$843,'03_Eventos_pagamentos'!$E$11:$E$843,A15,'03_Eventos_pagamentos'!$I$11:$I$843,"FAT. DIRETO") | N15: =K15+M15+N14 | O15: =X83 | P15: =O15+P14
A16: 3 | B16: =SUM(COUNTIF('03_Eventos_pagamentos'!$E$11:$E$697,'04_TOTALIZADORA'!A16)+COUNTIF('03_Eventos_pagamentos'!$E$766:$E$836,'04_TOTALIZADORA'!A16)) | C16: =SUMIF('03_Eventos_pagamentos'!$E$11:$E$699,A16,'03_Eventos_pagamentos'!$O$11:$O$697)+SUMIF('03_Eventos_pagamentos'!$E$766:$E$836,A16,'03_Eventos_pagamentos'!$O$766:$O$836) | D16: =COUNTIF('03_Eventos_pagamentos'!$E$702:$E$763,'04_TOTALIZADORA'!A16) | E16: =SUMIF('03_Eventos_pagamentos'!$E$702:$E$763,A16,'03_Eventos_pagamentos'!$O$702:$O$763) | F16: =C16+E16+F15 | G16: =C16+E16-M16 | H16: =SUMIF('03_Eventos_pagamentos'!$E$702:$E$763,F16,'03_Eventos_pagamentos'!$O$702:$O$763) | I16: =G16-H16 | J16: =I16+M16 | K16: =SUMIF('03_Eventos_pagamentos'!$P$11:$P$843,A17,'03_Eventos_pagamentos'!$Q$11:$Q$843) | L16: =K16+L15 | M16: =SUMIFS( '03_Eventos_pagamentos'!$O$11:$O$843,'03_Eventos_pagamentos'!$E$11:$E$843,A16,'03_Eventos_pagamentos'!$I$11:$I$843,"FAT. DIRETO") | N16: =K16+M16+N15 | P16: =O16+P15
A17: 4 | B17: =SUM(COUNTIF('03_Eventos_pagamentos'!$E$11:$E$697,'04_TOTALIZADORA'!A17)+COUNTIF('03_Eventos_pagamentos'!$E$766:$E$836,'04_TOTALIZADORA'!A17)) | C17: =SUMIF('03_Eventos_pagamentos'!$E$11:$E$699,A17,'03_Eventos_pagamentos'!$O$11:$O$697)+SUMIF('03_Eventos_pagamentos'!$E$766:$E$836,A17,'03_Eventos_pagamentos'!$O$766:$O$836) | D17: =COUNTIF('03_Eventos_pagamentos'!$E$702:$E$763,'04_TOTALIZADORA'!A17) | E17: =SUMIF('03_Eventos_pagamentos'!$E$702:$E$763,A17,'03_Eventos_pagamentos'!$O$702:$O$763) | F17: =C17+E17+F16 | G17: =C17+E17-M17 | H17: =SUMIF('03_Eventos_pagamentos'!$E$702:$E$763,F17,'03_Eventos_pagamentos'!$O$702:$O$763) | I17: =G17-H17 | J17: =I17+M17 | K17: =SUMIF('03_Eventos_pagamentos'!$P$11:$P$843,A18,'03_Eventos_pagamentos'!$Q$11:$Q$843) | L17: =K17+L16 | M17: =SUMIFS( '03_Eventos_pagamentos'!$O$11:$O$843,'03_Eventos_pagamentos'!$E$11:$E$843,A17,'03_Eventos_pagamentos'!$I$11:$I$843,"FAT. DIRETO") | N17: =K17+M17+N16 | P17: =O17+P16
A18: 5 | B18: =SUM(COUNTIF('03_Eventos_pagamentos'!$E$11:$E$697,'04_TOTALIZADORA'!A18)+COUNTIF('03_Eventos_pagamentos'!$E$766:$E$836,'04_TOTALIZADORA'!A18)) | C18: =SUMIF('03_Eventos_pagamentos'!$E$11:$E$699,A18,'03_Eventos_pagamentos'!$O$11:$O$697)+SUMIF('03_Eventos_pagamentos'!$E$766:$E$836,A18,'03_Eventos_pagamentos'!$O$766:$O$836) | D18: =COUNTIF('03_Eventos_pagamentos'!$E$702:$E$763,'04_TOTALIZADORA'!A18) | E18: =SUMIF('03_Eventos_pagamentos'!$E$702:$E$763,A18,'03_Eventos_pagamentos'!$O$702:$O$763) | F18: =C18+E18+F17 | G18: =C18+E18-M18 | H18: =SUMIF('03_Eventos_pagamentos'!$E$702:$E$763,F18,'03_Eventos_pagamentos'!$O$702:$O$763) | I18: =G18-H18 | J18: =I18+M18 | K18: =SUMIF('03_Eventos_pagamentos'!$P$11:$P$843,A19,'03_Eventos_pagamentos'!$Q$11:$Q$843) | L18: =K18+L17 | M18: =SUMIFS( '03_Eventos_pagamentos'!$O$11:$O$843,'03_Eventos_pagamentos'!$E$11:$E$843,A18,'03_Eventos_pagamentos'!$I$11:$I$843,"FAT. DIRETO") | N18: =K18+M18+N17 | P18: =O18+P17
